Workbook

Sheet Receitas
B5: PRESTAÇÃO DE CONTAS - MAIO/2026
B7: RECIBO | C7: ALUGUEL | D7: ENCARGOS | E7: ACORDO | F7: CONDOMÍNIO | G7: IPTU | H7: SEGURO | I7: IR | J7: TX BCO | K7: HONORÁRIOS | L7: OUTROS | M7: TOTAL
B8: Rua Florêncio de Abreu, 60 | C8: 12691.68 | D8: 0 | E8: 0 | F8: 0 | G8: 11802.24 | H8: 0 | I8: 0 | J8: 0 | K8: =(C8+D8+E8)*6% -> 761.5008 | L8: 0 | M8: =C8+D8+E8+F8+G8+H8+J8+L8-I8 -> 24493.92
B9: Rua Florêncio de Abreu, 66/70/74 | C9: 27461.37 | D9: 0 | E9: 0 | F9: 0 | G9: 11802.24 | H9: 0 | I9: 0 | J9: 0 | K9: =(C9+D9+E9)*6% -> 1647.6822 | L9: 0 | M9: =C9+D9+E9+F9+G9+H9+J9+L9-I9 -> 39263.61
B10: Rua 25 de Março, 669 | C10: =114027.58-9904.5-5281.24-29071.04 -> 69770.8 | D10: 0 | E10: 0 | F10: 0 | G10: 0 | H10: 0 | I10: 0 | J10: 0 | K10: =(C10+D10+E10)*6% -> 4186.248 | L10: 0 | M10: =C10+D10+E10+F10+G10+H10+J10+L10-I10 -> 69770.8
B11: Rua 25 de Março, 661 | C11: =262539.39-97971.06-19679.85 -> 144888.48 | D11: 0 | E11: 0 | F11: 0 | G11: 29268.39 | H11: 0 | I11: =145.51+145.51+695.47+695.47+7817.55+695.49 -> 10195 | J11: 0 | K11: =(C11+D11+E11)*6% -> 8693.3088 | L11: =1051.25+4794.07+1519.59 -> 7364.91 | M11: =C11+D11+E11+F11+G11+H11+J11+L11-I11 -> 171326.78
B12: Loja 1 | C12: =14443.96-9994.94 -> 4449.02 | D12: 0 | E12: 0 | F12: 3383.25 | G12: 165.26 | H12: 0 | I12: 0 | J12: 0 | K12: =(C12+D12+E12)*6% -> 266.9412 | L12: 0 | M12: =C12+D12+E12+F12+G12+H12+J12+L12-I12 -> 7997.53
B13: Loja 1A | C13: 1436.57 | D13: 0 | E13: 0 | F13: 419.69 | G13: 29.97 | H13: 0 | I13: 0 | J13: 0 | K13: =(C13+D13+E13)*6% -> 86.1942 | L13: 0 | M13: =C13+D13+E13+F13+G13+H13+J13+L13-I13 -> 1886.23
B14: Loja 1B | C14: 1036.03 | D14: 0 | E14: 0 | F14: 269.85 | G14: 19.31 | H14: 0 | I14: 0 | J14: 0 | K14: =(C14+D14+E14)*6% -> 62.1618 | L14: 0 | M14: =C14+D14+E14+F14+G14+H14+J14+L14-I14 -> 1325.19
B15: Loja 1C | C15: 0 | D15: 0 | E15: 0 | F15: 0 | G15: 0 | H15: 0 | I15: 0 | J15: 0 | K15: =(C15+D15+E15)*6% -> 0 | L15: 0 | M15: =C15+D15+E15+F15+G15+H15+J15+L15-I15 -> 0
B16: Loja 1C - SS | C16: 0 | D16: 0 | E16: 0 | F16: 0 | G16: 0 | H16: 0 | I16: 0 | J16: 0 | K16: =(C16+D16+E16)*6% -> 0 | L16: 0 | M16: =C16+D16+E16+F16+G16+H16+J16+L16-I16 -> 0
B17: Loja 2A -FRENTE | C17: 1666.77 | D17: 0 | E17: 0 | F17: 1526.98 | G17: 104.47 | H17: 0 | I17: 0 | J17: 0 | K17: =(C17+D17+E17)*6% -> 100.0062 | L17: 209.11 | M17: =C17+D17+E17+F17+G17+H17+J17+L17-I17 -> 3507.33
B18: Loja 2-QUADRADA | C18: 1342.42 | D18: 0 | E18: 0 | F18: 1574.98 | G18: 104.47 | H18: 0 | I18: 0 | J18: 0 | K18: =(C18+D18+E18)*6% -> 80.5452 | L18: 0 | M18: =C18+D18+E18+F18+G18+H18+J18+L18-I18 -> 3021.87
B19: Loja 2-QUADRADA | C19: 1342.42 | D19: 0 | E19: 0 | F19: 1574.98 | G19: 104.47 | H19: 0 | I19: 0 | J19: 0 | K19: =(C19+D19+E19)*6% -> 80.5452 | L19: 0 | M19: =C19+D19+E19+F19+G19+H19+J19+L19-I19 -> 3021.87
B20: Loja 3 | C20: =999.66 -> 999.66 | D20: 0 | E20: 0 | F20: 2062.85 | G20: 134.79 | H20: 0 | I20: 0 | J20: 0 | K20: =(C20+D20+E20)*6% -> 59.9796 | L20: 0 | M20: =C20+D20+E20+F20+G20+H20+J20+L20-I20 -> 3197.3
B21: Loja 4 | C21: =3428.34-2376.65 -> 1051.69 | F21: 2184.84 | G21: 130.1 | K21: =(C21+D21+E21)*6% -> 63.1014 | M21: =C21+D21+E21+F21+G21+H21+J21+L21-I21 -> 3366.63
B22: Loja 5 | C22: 0 | D22: 0 | E22: 0 | F22: 0 | G22: 0 | H22: 0 | I22: 0 | J22: 0 | K22: =(C22+D22+E22)*6% -> 0 | L22: 0 | M22: =C22+D22+E22+F22+G22+H22+J22+L22-I22 -> 0
B23: Loja 5A | C23: 1754.25 | D23: 0 | E23: 0 | F23: 424.49 | G23: 0 | H23: 0 | I23: 0 | J23: 0 | K23: =(C23+D23+E23)*6% -> 105.255 | L23: 0 | M23: =C23+D23+E23+F23+G23+H23+J23+L23-I23 -> 2178.74
B24: Loja 6/7 | C24: =6275.12-2523.47-467.82-760.25 -> 2523.58 | D24: 0 | E24: 0 | F24: 3018.63 | G24: =81.57+78.84 -> 160.41 | H24: 0 | I24: 0 | J24: 0 | K24: =(C24+D24+E24)*6% -> 151.4148 | L24: 0 | M24: =C24+D24+E24+F24+G24+H24+J24+L24-I24 -> 5702.62
B25: Loja 7A | C25: 0 | D25: 0 | E25: 0 | F25: 0 | G25: 0 | H25: 0 | I25: 0 | J25: 0 | K25: =(C25+D25+E25)*6% -> 0 | L25: 0 | M25: =C25+D25+E25+F25+G25+H25+J25+L25-I25 -> 0
B26: Loja 8A | C26: 800.24 | D26: 0 | E26: 0 | F26: 666.47 | G26: 21.07 | H26: 0 | I26: 0 | J26: 0 | K26: =(C26+D26+E26)*6% -> 48.0144 | L26: 0 | M26: =C26+D26+E26+F26+G26+H26+J26+L26-I26 -> 1487.78
B27: Loja 8A | C27: 0 | D27: 0 | E27: 900 | F27: 0 | G27: 0 | H27: 0 | I27: 0 | J27: 0 | K27: =(C27+D27+E27)*6% -> 54 | L27: 0 | M27: =C27+D27+E27+F27+G27+H27+J27+L27-I27 -> 900
B28: Loja 8B | C28: =1232.86-378.73 -> 854.13 | D28: 0 | E28: 0 | F28: 435.04 | G28: 13.76 | H28: 0 | I28: 0 | J28: 0 | K28: =(C28+D28+E28)*6% -> 51.2478 | L28: 0 | M28: =C28+D28+E28+F28+G28+H28+J28+L28-I28 -> 1302.93
B29: Loja 8-8C | C29: =562.54-89.91 -> 472.63 | E29: 0 | F29: 701.03 | G29: 59.78 | K29: =(C29+D29+E29)*6% -> 28.3578 | L29: 0 | M29: =C29+D29+E29+F29+G29+H29+J29+L29-I29 -> 1233.44
B30: Loja 8D | C30: 594.74 | D30: 0 | E30: 0 | F30: 1189.92 | G30: 12.77 | H30: 0 | I30: 0 | J30: 0 | K30: =(C30+D30+E30)*6% -> 35.6844 | L30: 0 | M30: =C30+D30+E30+F30+G30+H30+J30+L30-I30 -> 1797.43
B31: Loja 9 | C31: =2285.89 -> 2285.89 | D31: 0 | E31: 0 | F31: 2511.34 | G31: 147.84 | H31: 0 | I31: 0 | J31: 0 | K31: =(C31+D31+E31)*6% -> 137.1534 | L31: 0 | M31: =C31+D31+E31+F31+G31+H31+J31+L31-I31 -> 4945.07
B32: Loja 10 | C32: =2260.34 -> 2260.34 | D32: 0 | E32: 0 | F32: 1657.58 | G32: 87.48 | H32: 0 | I32: 0 | J32: 0 | K32: =(C32+D32+E32)*6% -> 135.6204 | L32: 0 | M32: =C32+D32+E32+F32+G32+H32+J32+L32-I32 -> 4005.4
B33: Loja 11 | C33: =2322.36 -> 2322.36 | D33: 0 | E33: 0 | F33: 1575.95 | G33: 83.54 | H33: 0 | I33: 0 | J33: 0 | K33: =(C33+D33+E33)*6% -> 139.3416 | L33: 0 | M33: =C33+D33+E33+F33+G33+H33+J33+L33-I33 -> 3981.85
B34: Loja 12 | C34: 2201.65 | D34: 0 | E34: 0 | F34: 2915.68 | G34: 147.84 | H34: 0 | I34: 0 | J34: 0 | K34: =(C34+D34+E34)*6% -> 132.099 | L34: 0 | M34: =C34+D34+E34+F34+G34+H34+J34+L34-I34 -> 5265.17
B35: Loja 13 | C35: 1147.54 | D35: 0 | E35: 0 | F35: 1067.93 | G35: 63.27 | H35: 0 | I35: 0 | J35: 0 | K35: =(C35+D35+E35)*6% -> 68.8524 | L35: 0 | M35: =C35+D35+E35+F35+G35+H35+J35+L35-I35 -> 2278.74
B36: Loja 13A | C36: =1825.86-156.69 -> 1669.17 | D36: 0 | E36: 0 | F36: 1162.03 | G36: 68.8 | H36: 0 | I36: 0 | J36: 0 | K36: =(C36+D36+E36)*6% -> 100.1502 | L36: 0 | M36: =C36+D36+E36+F36+G36+H36+J36+L36-I36 -> 2900
B37: Loja 14 | C37: 876.97 | D37: 0 | E37: 0 | F37: 565.64 | G37: 97.34 | H37: 0 | I37: 0 | J37: 0 | K37: =(C37+D37+E37)*6% -> 52.6182 | L37: 0 | M37: =C37+D37+E37+F37+G37+H37+J37+L37-I37 -> 1539.95
B38: Loja 15 | C38: =1848.21 -> 1848.21 | D38: 0 | E38: 0 | F38: 681.87 | G38: 52.56 | H38: 0 | I38: 0 | J38: 0 | K38: =(C38+D38+E38)*6% -> 110.8926 | L38: 0 | M38: =C38+D38+E38+F38+G38+H38+J38+L38-I38 -> 2582.64
B39: Loja 17 | C39: 1137.96 | D39: =127.3+54.39+109.17 -> 290.86 | E39: 0 | F39: 675.04 | G39: 0 | H39: 0 | I39: 0 | J39: 0 | K39: =(C39+D39+E39)*6% -> 85.7292 | L39: 0 | M39: =C39+D39+E39+F39+G39+H39+J39+L39-I39 -> 2103.86
B40: Loja 17A | C40: =1269.15-800 -> 469.15 | D40: 0 | E40: 0 | F40: 508.95 | G40: 21.9 | H40: 0 | I40: 0 | J40: 0 | K40: =(C40+D40+E40)*6% -> 28.149 | L40: 0 | M40: =C40+D40+E40+F40+G40+H40+J40+L40-I40 -> 1000
B41: Vitrine 1A | C41: 159.56 | D41: 0 | E41: 0 | F41: 0 | G41: 0 | H41: 0 | I41: 0 | J41: 0 | K41: =(C41+D41+E41)*6% -> 9.5736 | L41: 0 | M41: =C41+D41+E41+F41+G41+H41+J41+L41-I41 -> 159.56
B42: Vitrine 03 | C42: 324.7 | D42: 0 | E42: 0 | F42: 0 | G42: 0 | H42: 0 | I42: 0 | J42: 0 | K42: =(C42+D42+E42)*6% -> 19.482 | L42: 0 | M42: =C42+D42+E42+F42+G42+H42+J42+L42-I42 -> 324.7
B43: Vitrine 4A | C43: 416.56 | D43: 0 | E43: 0 | F43: 0 | G43: 0 | H43: 0 | I43: 0 | J43: 0 | K43: =(C43+D43+E43)*6% -> 24.9936 | L43: 0 | M43: =C43+D43+E43+F43+G43+H43+J43+L43-I43 -> 416.56
B44: Vitrine 5A/5B | C44: 336.87 | D44: 0 | E44: 0 | F44: 0 | G44: 0 | H44: 0 | I44: 0 | J44: 0 | K44: =(C44+D44+E44)*6% -> 20.2122 | L44: 0 | M44: =C44+D44+E44+F44+G44+H44+J44+L44-I44 -> 336.87
B45: Vitrine 08 | C45: 164.26 | D45: 0 | E45: 0 | F45: 0 | G45: 0 | H45: 0 | I45: 0 | J45: 0 | K45: =(C45+D45+E45)*6% -> 9.8556 | L45: 0 | M45: =C45+D45+E45+F45+G45+H45+J45+L45-I45 -> 164.26
...

Sheet Dist. Receitas
B5: DISTRIBUIÇÃO DE RECEITAS - MAIO/2026
B7: Receitas | N7: ROPSIME C | O7: CAROLINE | P7: THYAGO | Q7: FREDERICO | R7: EDDA | S7: CLAUDINA | T7: VARAM | U7: M. TERESA | V7: HENRIQUE | W7: ADRIANA | X7: CAROLINA | Y7: FKZ | Z7: M. ANTONIO | AA7: JULIANA | AB7: MONIQUE | AC7: VIVIANE | AD7: DENISE | AE7: ROPSIMÉ | AF7: KEUTE | AG7: HALLELUJAH | AH7: ROKE
N8: 0.24 | O8: 0 | P8: 0 | Q8: 0 | R8: 0 | S8: 0.04 | T8: 0.04 | U8: 0.02 | V8: 0.02 | W8: 0 | X8: 0 | Y8: 0.04 | Z8: 0 | AA8: 0.05 | AB8: 0.05 | AC8: 0.05 | AD8: 0.05 | AE8: 0 | AF8: 0.1 | AG8: 0.1 | AH8: 0.2
B9: RECIBO | C9: ALUGUEL | M9: ALUGUEL
B10: Rua Florêncio de Abreu, 60 | C10: 12691.68 | D10: 0 | E10: 0 | F10: 0 | G10: 11802.24 | H10: 0 | I10: 0 | J10: 0 | K10: =(C10+D10+E10)*6% -> 761.5008 | L10: 0 | M10: =C10+D10+E10+F10+G10+H10+J10+L10-I10 -> 24493.92 | N10: =$M$10*N8 -> 5878.5408 | O10: =$M$10*O8 -> 0 | P10: =$M$10*P8 -> 0 | Q10: =$M$10*Q8 -> 0 | R10: =$M$10*R8 -> 0 | S10: =$M$10*S8 -> 979.7568 | T10: =$M$10*T8 -> 979.7568 | U10: =$M$10*U8 -> 489.8784 | ... AH10: =$M$10*AH8 -> 4898.784
B11: Rua Florêncio de Abreu, 66/70/74 | C11: 27461.37 | D11: 0 | E11: 0 | F11: 0 | G11: 11802.24 | H11: 0 | I11: 0 | J11: 0 | K11: =(C11+D11+E11)*6% -> 1647.6822 | L11: 0 | M11: =C11+D11+E11+F11+G11+H11+J11+L11-I11 -> 39263.61 | N11: =$M$11*N8 -> 9423.2664 | O11: =$M$11*O8 -> 0 | P11: =$M$11*P8 -> 0 | Q11: =$M$11*Q8 -> 0 | R11: =$M$11*R8 -> 0 | S11: =$M$11*S8 -> 1570.5444 | T11: =$M$11*T8 -> 1570.5444 | U11: =$M$11*U8 -> 785.2722 | ... AH11: =$M$11*AH8 -> 7852.722
B12: Rua 25 de Março, 669 | C12: =114027.58-9904.5-5281.24-29071.04 -> 69770.8 | D12: 0 | E12: 0 | F12: 0 | G12: 0 | H12: 0 | I12: 0 | J12: 0 | K12: =(C12+D12+E12)*6% -> 4186.248 | L12: 0 | M12: =C12+D12+E12+F12+G12+H12+J12+L12-I12 -> 69770.8 | N12: =$M$12*N8 -> 16744.992 | O12: =$M$12*O8 -> 0 | P12: =$M$12*P8 -> 0 | Q12: =$M$12*Q8 -> 0 | R12: =$M$12*R8 -> 0 | S12: =$M$12*S8 -> 2790.832 | T12: =$M$12*T8 -> 2790.832 | U12: =$M$12*U8 -> 1395.416 | ... AH12: =$M$12*AH8 -> 13954.16
B13: Rua 25 de Março, 661 | C13: =262539.39-97971.06-19679.85 -> 144888.48 | D13: 0 | E13: 0 | F13: 0 | G13: 29268.39 | H13: 0 | I13: =145.51+145.51+695.47+695.47+7817.55+695.49 -> 10195 | J13: 0 | K13: =(C13+D13+E13)*6% -> 8693.3088 | L13: =1051.25+4794.07+1519.59 -> 7364.91 | M13: =C13+D13+E13+F13+G13+H13+J13+L13-I13 -> 171326.78 | N13: =$M$13*$N8-7913.17 -> 33205.257 | O13: =$M$13*O$8 -> 0 | P13: =$M$13*P$8 -> 0 | Q13: =$M$13*Q$8 -> 0 | R13: =$M$13*R$8 -> 0 | S13: =$M$13*S$8-422.44 -> 6430.6312 | T13: =$M$13*T$8-422.44 -> 6430.6312 | U13: =$M$13*U$8 -> 3426.5356 | V13: =$M$13*V$8 -> 3426.5356 | W13: =$M$13*W$8 -> 0 | X13: =$M$13*X$8 -> 0 | Y13: =$M$13*Y$8 -> 6853.0712 | Z13: =$M$13*Z$8 -> 0 | AA13: =$M$13*AA$8-796.97 -> 7769.369 | AB13: =$M$13*AB$8-796.97 -> 7769.369 | AC13: =$M$13*AC$8-796.97 -> 7769.369 | AD13: =$M$13*AD$8 -> 8566.339 | AE13: =$M$13*AE$8 -> 0 | AF13: =$M$13*AF$8 -> 17132.678 | AG13: =$M$13*AG$8 -> 17132.678 | AH13: =$M$13*AH$8 -> 34265.356
B14: Receitas | N14: ROPSIME C | O14: CAROLINE | P14: THYAGO | Q14: FREDERICO | R14: EDDA | S14: CLAUDINA | T14: VARAM | U14: M. TERESA | V14: HENRIQUE | W14: ADRIANA | X14: CAROLINA | Y14: FKZ | Z14: M. ANTONIO | AA14: JULIANA | AB14: MONIQUE | AC14: VIVIANE | AD14: DENISE | AE14: ROPSIMÉ | AF14: KEUTE | AG14: HALLELUJAH | AH14: ROKE
N15: 0.24 | O15: 0.07916667 | P15: 0.06666667 | Q15: 0.07916667 | R15: 0 | S15: 0.0525 | T15: 0.04 | U15: 0.02 | V15: 0.02 | W15: 0.04 | X15: 0 | Y15: 0 | Z15: 0.0125 | AA15: 0 | AB15: 0.05 | AC15: 0.05 | AD15: 0.05 | AE15: 0.2 | AF15: 0 | AG15: 0 | AH15: 0
B16: RECIBO | C16: ALUGUEL | M16: ALUGUEL
B17: Loja 1 | C17: =14443.96-9994.94 -> 4449.02 | D17: 0 | E17: 0 | F17: 3383.25 | G17: 165.26 | H17: 0 | I17: 0 | J17: 0 | K17: =(C17+D17+E17)*6% -> 266.9412 | L17: 0 | M17: =C17+D17+E17+F17+G17+H17+J17+L17-I17 -> 7997.53 | N17: =M17*$N$15 -> 1919.4072 | O17: =M17*$O$15 -> 633.13782 | P17: =M17*$P$15 -> 533.16869 | Q17: =M17*$Q$15 -> 633.13782 | R17: =M17*$R$15 -> 0 | S17: =M17*$S$15 -> 419.87032 | T17: =M17*$T$15 -> 319.9012 | U17: =M17*$U$15 -> 159.9506 | V17: =M17*$U$15 -> 159.9506 | W17: =M17*$W$15 -> 319.9012 | X17: =M17*$X$15 -> 0 | Y17: =N17*$X$15 -> 0 | Z17: =M17*$Z$15 -> 99.969125 | AA17: =M17*$AA$15 -> 0 | AB17: =M17*$AB$15 -> 399.8765 | AC17: =M17*$AC$15 -> 399.8765 | AD17: =M17*$AD$15 -> 399.8765 | AE17: =M17*$AE$15 -> 1599.506 | AF17: =L17*$AH$15 -> 0 | AG17: =M17*$AG$15 -> 0 | AH17: =M17*$AH$15 -> 0
B18: Loja 1A | C18: 1436.57 | D18: 0 | E18: 0 | F18: 419.69 | G18: 29.97 | H18: 0 | I18: 0 | J18: 0 | K18: =(C18+D18+E18)*6% -> 86.1942 | L18: 0 | M18: =C18+D18+E18+F18+G18+H18+J18+L18-I18 -> 1886.23 | N18: =M18*$N$15 -> 452.6952 | O18: =M18*$O$15 -> 149.32655 | P18: =M18*$P$15 -> 125.74867 | Q18: =M18*$Q$15 -> 149.32655 | R18: =M18*$R$15 -> 0 | S18: =M18*$S$15 -> 99.027075 | T18: =M18*$T$15 -> 75.4492 | U18: =M18*$U$15 -> 37.7246 | V18: =M18*$U$15 -> 37.7246 | W18: =M18*$W$15 -> 75.4492 | X18: =M18*$X$15 -> 0 | Y18: =N18*$X$15 -> 0 | Z18: =M18*$Z$15 -> 23.577875 | AA18: =M18*$AA$15 -> 0 | AB18: =M18*$AB$15 -> 94.3115 | AC18: =M18*$AC$15 -> 94.3115 | AD18: =M18*$AD$15 -> 94.3115 | AE18: =M18*$AE$15 -> 377.246 | AF18: =L18*$AH$15 -> 0 | AG18: =M18*$AG$15 -> 0 | AH18: =M18*$AH$15 -> 0
B19: Loja 1B | C19: 1036.03 | D19: 0 | E19: 0 | F19: 269.85 | G19: 19.31 | H19: 0 | I19: 0 | J19: 0 | K19: =(C19+D19+E19)*6% -> 62.1618 | L19: 0 | M19: =C19+D19+E19+F19+G19+H19+J19+L19-I19 -> 1325.19 | N19: =M19*$N$15 -> 318.0456 | O19: =M19*$O$15 -> 104.91088 | P19: =M19*$P$15 -> 88.346004 | Q19: =M19*$Q$15 -> 104.91088 | R19: =M19*$R$15 -> 0 | S19: =M19*$S$15 -> 69.572475 | T19: =M19*$T$15 -> 53.0076 | U19: =M19*$U$15 -> 26.5038 | V19: =M19*$U$15 -> 26.5038 | W19: =M19*$W$15 -> 53.0076 | X19: =M19*$X$15 -> 0 | Y19: =N19*$X$15 -> 0 | Z19: =M19*$Z$15 -> 16.564875 | AA19: =M19*$AA$15 -> 0 | AB19: =M19*$AB$15 -> 66.2595 | AC19: =M19*$AC$15 -> 66.2595 | AD19: =M19*$AD$15 -> 66.2595 | AE19: =M19*$AE$15 -> 265.038 | AF19: =L19*$AH$15 -> 0 | AG19: =M19*$AG$15 -> 0 | AH19: =M19*$AH$15 -> 0
B20: Loja 1C | C20: 0 | D20: 0 | E20: 0 | F20: 0 | G20: 0 | H20: 0 | I20: 0 | J20: 0 | K20: =(C20+D20+E20)*6% -> 0 | L20: 0 | M20: =C20+D20+E20+F20+G20+H20+J20+L20-I20 -> 0 | N20: =M20*$N$15 -> 0 | O20: =M20*$O$15 -> 0 | P20: =M20*$P$15 -> 0 | Q20: =M20*$Q$15 -> 0 | R20: =M20*$R$15 -> 0 | S20: =M20*$S$15 -> 0 | T20: =M20*$T$15 -> 0 | U20: =M20*$U$15 -> 0 | V20: =M20*$U$15 -> 0 | W20: =M20*$W$15 -> 0 | X20: =M20*$X$15 -> 0 | Y20: =N20*$X$15 -> 0 | Z20: =M20*$Z$15 -> 0 | AA20: =M20*$AA$15 -> 0 | AB20: =M20*$AB$15 -> 0 | AC20: =M20*$AC$15 -> 0 | AD20: =M20*$AD$15 -> 0 | AE20: =M20*$AE$15 -> 0 | AF20: =L20*$AH$15 -> 0 | AG20: =M20*$AG$15 -> 0 | AH20: =M20*$AH$15 -> 0
B21: Loja 1C - SS | C21: 0 | D21: 0 | E21: 0 | F21: 0 | G21: 0 | H21: 0 | I21: 0 | J21: 0 | K21: =(C21+D21+E21)*6% -> 0 | L21: 0 | M21: =C21+D21+E21+F21+G21+H21+J21+L21-I21 -> 0 | N21: =M21*$N$15 -> 0 | O21: =M21*$O$15 -> 0 | P21: =M21*$P$15 -> 0 | Q21: =M21*$Q$15 -> 0 | R21: =M21*$R$15 -> 0 | S21: =M21*$S$15 -> 0 | T21: =M21*$T$15 -> 0 | U21: =M21*$U$15 -> 0 | V21: =M21*$U$15 -> 0 | W21: =M21*$W$15 -> 0 | X21: =M21*$X$15 -> 0 | Y21: =N21*$X$15 -> 0 | Z21: =M21*$Z$15 -> 0 | AA21: =M21*$AA$15 -> 0 | AB21: =M21*$AB$15 -> 0 | AC21: =M21*$AC$15 -> 0 | AD21: =M21*$AD$15 -> 0 | AE21: =M21*$AE$15 -> 0 | AF21: =L21*$AH$15 -> 0 | AG21: =M21*$AG$15 -> 0 | AH21: =M21*$AH$15 -> 0
B22: Loja 2A -FRENTE | C22: 1666.77 | D22: 0 | E22: 0 | F22: 1526.98 | G22: 104.47 | H22: 0 | I22: 0 | J22: 0 | K22: =(C22+D22+E22)*6% -> 100.0062 | L22: 209.11 | M22: =C22+D22+E22+F22+G22+H22+J22+L22-I22 -> 3507.33 | N22: =M22*$N$15 -> 841.7592 | O22: =M22*$O$15 -> 277.66364 | P22: =M22*$P$15 -> 233.82201 | Q22: =M22*$Q$15 -> 277.66364 | R22: =M22*$R$15 -> 0 | S22: =M22*$S$15 -> 184.13482 | T22: =M22*$T$15 -> 140.2932 | U22: =M22*$U$15 -> 70.1466 | V22: =M22*$U$15 -> 70.1466 | W22: =M22*$W$15 -> 140.2932 | X22: =M22*$X$15 -> 0 | Y22: =N22*$X$15 -> 0 | Z22: =M22*$Z$15 -> 43.841625 | AA22: =M22*$AA$15 -> 0 | AB22: =M22*$AB$15 -> 175.3665 | AC22: =M22*$AC$15 -> 175.3665 | AD22: =M22*$AD$15 -> 175.3665 | AE22: =M22*$AE$15 -> 701.466 | AF22: =L22*$AH$15 -> 0 | AG22: =M22*$AG$15 -> 0 | AH22: =M22*$AH$15 -> 0
B23: Loja 2-QUADRADA | C23: 1342.42 | D23: 0 | E23: 0 | F23: 1574.98 | G23: 104.47 | H23: 0 | I23: 0 | J23: 0 | K23: =(C23+D23+E23)*6% -> 80.5452 | L23: 0 | M23: =C23+D23+E23+F23+G23+H23+J23+L23-I23 -> 3021.87 | N23: =M23*$N$15 -> 725.2488 | O23: =M23*$O$15 -> 239.23139 | P23: =M23*$P$15 -> 201.45801 | Q23: =M23*$Q$15 -> 239.23139 | R23: =M23*$R$15 -> 0 | S23: =M23*$S$15 -> 158.64817 | T23: =M23*$T$15 -> 120.8748 | U23: =M23*$U$15 -> 60.4374 | V23: =M23*$U$15 -> 60.4374 | W23: =M23*$W$15 -> 120.8748 | X23: =M23*$X$15 -> 0 | Y23: =N23*$X$15 -> 0 | Z23: =M23*$Z$15 -> 37.773375 | AA23: =M23*$AA$15 -> 0 | AB23: =M23*$AB$15 -> 151.0935 | AC23: =M23*$AC$15 -> 151.0935 | AD23: =M23*$AD$15 -> 151.0935 | AE23: =M23*$AE$15 -> 604.374 | AF23: =L23*$AH$15 -> 0 | AG23: =M23*$AG$15 -> 0 | AH23: =M23*$AH$15 -> 0
B24: Loja 2-QUADRADA | C24: 1342.42 | D24: 0 | E24: 0 | F24: 1574.98 | G24: 104.47 | H24: 0 | I24: 0 | J24: 0 | K24: =(C24+D24+E24)*6% -> 80.5452 | L24: 0 | M24: =C24+D24+E24+F24+G24+H24+J24+L24-I24 -> 3021.87 | N24: =M24*$N$15 -> 725.2488 | O24: =M24*$O$15 -> 239.23139 | P24: =M24*$P$15 -> 201.45801 | Q24: =M24*$Q$15 -> 239.23139 | R24: =M24*$R$15 -> 0 | S24: =M24*$S$15 -> 158.64817 | T24: =M24*$T$15 -> 120.8748 | U24: =M24*$U$15 -> 60.4374 | V24: =M24*$U$15 -> 60.4374 | W24: =M24*$W$15 -> 120.8748 | X24: =M24*$X$15 -> 0 | Y24: =N24*$X$15 -> 0 | Z24: =M24*$Z$15 -> 37.773375 | AA24: =M24*$AA$15 -> 0 | AB24: =M24*$AB$15 -> 151.0935 | AC24: =M24*$AC$15 -> 151.0935 | AD24: =M24*$AD$15 -> 151.0935 | AE24: =M24*$AE$15 -> 604.374 | AF24: =L24*$AH$15 -> 0 | AG24: =M24*$AG$15 -> 0 | AH24: =M24*$AH$15 -> 0
B25: Loja 3 | C25: =999.66 -> 999.66 | D25: 0 | E25: 0 | F25: 2062.85 | G25: 134.79 | H25: 0 | I25: 0 | J25: 0 | K25: =(C25+D25+E25)*6% -> 59.9796 | L25: 0 | M25: =C25+D25+E25+F25+G25+H25+J25+L25-I25 -> 3197.3 | N25: =M25*$N$15 -> 767.352 | O25: =M25*$O$15 -> 253.11959 | P25: =M25*$P$15 -> 213.15334 | Q25: =M25*$Q$15 -> 253.11959 | R25: =M25*$R$15 -> 0 | S25: =M25*$S$15 -> 167.85825 | T25: =M25*$T$15 -> 127.892 | U25: =M25*$U$15 -> 63.946 | V25: =M25*$U$15 -> 63.946 | W25: =M25*$W$15 -> 127.892 | X25: =M25*$X$15 -> 0 | Y25: =N25*$X$15 -> 0 | Z25: =M25*$Z$15 -> 39.96625 | AA25: =M25*$AA$15 -> 0 | AB25: =M25*$AB$15 -> 159.865 | AC25: =M25*$AC$15 -> 159.865 | AD25: =M25*$AD$15 -> 159.865 | AE25: =M25*$AE$15 -> 639.46 | AF25: =L25*$AH$15 -> 0 | AG25: =M25*$AG$15 -> 0 | AH25: =M25*$AH$15 -> 0
B26: Loja 4 | C26: =3428.34-2376.65 -> 1051.69 | F26: 2184.84 | G26: 130.1 | K26: =(C26+D26+E26)*6% -> 63.1014 | M26: =C26+D26+E26+F26+G26+H26+J26+L26-I26 -> 3366.63 | N26: =M26*$N$15 -> 807.9912 | O26: =M26*$O$15 -> 266.52489 | P26: =M26*$P$15 -> 224.44201 | Q26: =M26*$Q$15 -> 266.52489 | R26: =M26*$R$15 -> 0 | S26: =M26*$S$15 -> 176.74808 | T26: =M26*$T$15 -> 134.6652 | U26: =M26*$U$15 -> 67.3326 | V26: =M26*$U$15 -> 67.3326 | W26: =M26*$W$15 -> 134.6652 | X26: =M26*$X$15 -> 0 | Y26: =N26*$X$15 -> 0 | Z26: =M26*$Z$15 -> 42.082875 | AA26: =M26*$AA$15 -> 0 | AB26: =M26*$AB$15 -> 168.3315 | AC26: =M26*$AC$15 -> 168.3315 | AD26: =M26*$AD$15 -> 168.3315 | AE26: =M26*$AE$15 -> 673.326 | AF26: =L26*$AH$15 -> 0 | AG26: =M26*$AG$15 -> 0 | AH26: =M26*$AH$15 -> 0
B27: Loja 5 | C27: 0 | D27: 0 | E27: 0 | F27: 0 | G27: 0 | H27: 0 | I27: 0 | J27: 0 | K27: =(C27+D27+E27)*6% -> 0 | L27: 0 | M27: =C27+D27+E27+F27+G27+H27+J27+L27-I27 -> 0 | N27: =M27*$N$15 -> 0 | O27: =M27*$O$15 -> 0 | P27: =M27*$P$15 -> 0 | Q27: =M27*$Q$15 -> 0 | R27: =M27*$R$15 -> 0 | S27: =M27*$S$15 -> 0 | T27: =M27*$T$15 -> 0 | U27: =M27*$U$15 -> 0 | V27: =M27*$U$15 -> 0 | W27: =M27*$W$15 -> 0 | X27: =M27*$X$15 -> 0 | Y27: =N27*$X$15 -> 0 | Z27: =M27*$Z$15 -> 0 | AA27: =M27*$AA$15 -> 0 | AB27: =M27*$AB$15 -> 0 | AC27: =M27*$AC$15 -> 0 | AD27: =M27*$AD$15 -> 0 | AE27: =M27*$AE$15 -> 0 | AF27: =L27*$AH$15 -> 0 | AG27: =M27*$AG$15 -> 0 | AH27: =M27*$AH$15 -> 0
B28: Loja 5A | C28: 1754.25 | D28: 0 | E28: 0 | F28: 424.49 | G28: 0 | H28: 0 | I28: 0 | J28: 0 | K28: =(C28+D28+E28)*6% -> 105.255 | L28: 0 | M28: =C28+D28+E28+F28+G28+H28+J28+L28-I28 -> 2178.74 | N28: =M28*$N$15 -> 522.8976 | O28: =M28*$O$15 -> 172.48359 | P28: =M28*$P$15 -> 145.24934 | Q28: =M28*$Q$15 -> 172.48359 | R28: =M28*$R$15 -> 0 | S28: =M28*$S$15 -> 114.38385 | T28: =M28*$T$15 -> 87.1496 | U28: =M28*$U$15 -> 43.5748 | V28: =M28*$U$15 -> 43.5748 | W28: =M28*$W$15 -> 87.1496 | X28: =M28*$X$15 -> 0 | Y28: =N28*$X$15 -> 0 | Z28: =M28*$Z$15 -> 27.23425 | AA28: =M28*$AA$15 -> 0 | AB28: =M28*$AB$15 -> 108.937 | AC28: =M28*$AC$15 -> 108.937 | AD28: =M28*$AD$15 -> 108.937 | AE28: =M28*$AE$15 -> 435.748 | AF28: =L28*$AH$15 -> 0 | AG28: =M28*$AG$15 -> 0 | AH28: =M28*$AH$15 -> 0
B29: Loja 6/7 | C29: =6275.12-2523.47-467.82-760.25 -> 2523.58 | D29: 0 | E29: 0 | F29: 3018.63 | G29: =81.57+78.84 -> 160.41 | H29: 0 | I29: 0 | J29: 0 | K29: =(C29+D29+E29)*6% -> 151.4148 | L29: 0 | M29: =C29+D29+E29+F29+G29+H29+J29+L29-I29 -> 5702.62 | N29: =M29*$N$15 -> 1368.6288 | O29: =M29*$O$15 -> 451.45744 | P29: =M29*$P$15 -> 380.17469 | Q29: =M29*$Q$15 -> 451.45744 | R29: =M29*$R$15 -> 0 | S29: =M29*$S$15 -> 299.38755 | T29: =M29*$T$15 -> 228.1048 | U29: =M29*$U$15 -> 114.0524 | V29: =M29*$U$15 -> 114.0524 | W29: =M29*$W$15 -> 228.1048 | X29: =M29*$X$15 -> 0 | Y29: =N29*$X$15 -> 0 | Z29: =M29*$Z$15 -> 71.28275 | AA29: =M29*$AA$15 -> 0 | AB29: =M29*$AB$15 -> 285.131 | AC29: =M29*$AC$15 -> 285.131 | AD29: =M29*$AD$15 -> 285.131 | AE29: =M29*$AE$15 -> 1140.524 | AF29: =L29*$AH$15 -> 0 | AG29: =M29*$AG$15 -> 0 | AH29: =M29*$AH$15 -> 0
B30: Loja 7A | C30: 0 | D30: 0 | E30: 0 | F30: 0 | G30: 0 | H30: 0 | I30: 0 | J30: 0 | K30: =(C30+D30+E30)*6% -> 0 | L30: 0 | M30: =C30+D30+E30+F30+G30+H30+J30+L30-I30 -> 0 | N30: =M30*$N$15 -> 0 | O30: =M30*$O$15 -> 0 | P30: =M30*$P$15 -> 0 | Q30: =M30*$Q$15 -> 0 | R30: =M30*$R$15 -> 0 | S30: =M30*$S$15 -> 0 | T30: =M30*$T$15 -> 0 | U30: =M30*$U$15 -> 0 | V30: =M30*$U$15 -> 0 | W30: =M30*$W$15 -> 0 | X30: =M30*$X$15 -> 0 | Y30: =N30*$X$15 -> 0 | Z30: =M30*$Z$15 -> 0 | AA30: =M30*$AA$15 -> 0 | AB30: =M30*$AB$15 -> 0 | AC30: =M30*$AC$15 -> 0 | AD30: =M30*$AD$15 -> 0 | AE30: =M30*$AE$15 -> 0 | AF30: =L30*$AH$15 -> 0 | AG30: =M30*$AG$15 -> 0 | AH30: =M30*$AH$15 -> 0
B31: Loja 8A | C31: 800.24 | D31: 0 | E31: 0 | F31: 666.47 | G31: 21.07 | H31: 0 | I31: 0 | J31: 0 | K31: =(C31+D31+E31)*6% -> 48.0144 | L31: 0 | M31: =C31+D31+E31+F31+G31+H31+J31+L31-I31 -> 1487.78 | N31: =M31*$N$15 -> 357.0672 | O31: =M31*$O$15 -> 117.78259 | P31: =M31*$P$15 -> 99.185338 | Q31: =M31*$Q$15 -> 117.78259 | R31: =M31*$R$15 -> 0 | S31: =M31*$S$15 -> 78.10845 | T31: =M31*$T$15 -> 59.5112 | U31: =M31*$U$15 -> 29.7556 | V31: =M31*$U$15 -> 29.7556 | W31: =M31*$W$15 -> 59.5112 | X31: =M31*$X$15 -> 0 | Y31: =N31*$X$15 -> 0 | Z31: =M31*$Z$15 -> 18.59725 | AA31: =M31*$AA$15 -> 0 | AB31: =M31*$AB$15 -> 74.389 | AC31: =M31*$AC$15 -> 74.389 | AD31: =M31*$AD$15 -> 74.389 | AE31: =M31*$AE$15 -> 297.556 | AF31: =L31*$AH$15 -> 0 | AG31: =M31*$AG$15 -> 0 | AH31: =M31*$AH$15 -> 0
B32: Loja 8A | C32: 0 | D32: 0 | E32: 900 | F32: 0 | G32: 0 | H32: 0 | I32: 0 | J32: 0 | K32: =(C32+D32+E32)*6% -> 54 | L32: 0 | M32: =C32+D32+E32+F32+G32+H32+J32+L32-I32 -> 900 | N32: =M32*$N$15 -> 216 | O32: =M32*$O$15 -> 71.250003 | P32: =M32*$P$15 -> 60.000003 | Q32: =M32*$Q$15 -> 71.250003 | R32: =M32*$R$15 -> 0 | S32: =M32*$S$15 -> 47.25 | T32: =M32*$T$15 -> 36 | U32: =M32*$U$15 -> 18 | V32: =M32*$U$15 -> 18 | W32: =M32*$W$15 -> 36 | X32: =M32*$X$15 -> 0 | Y32: =N32*$X$15 -> 0 | Z32: =M32*$Z$15 -> 11.25 | AA32: =M32*$AA$15 -> 0 | AB32: =M32*$AB$15 -> 45 | AC32: =M32*$AC$15 -> 45 | AD32: =M32*$AD$15 -> 45 | AE32: =M32*$AE$15 -> 180 | AF32: =L32*$AH$15 -> 0 | AG32: =M32*$AG$15 -> 0 | AH32: =M32*$AH$15 -> 0
B33: Loja 8B | C33: =1232.86-378.73 -> 854.13 | D33: 0 | E33: 0 | F33: 435.04 | G33: 13.76 | H33: 0 | I33: 0 | J33: 0 | K33: =(C33+D33+E33)*6% -> 51.2478 | L33: 0 | M33: =C33+D33+E33+F33+G33+H33+J33+L33-I33 -> 1302.93 | N33: =M33*$N$15 -> 312.7032 | O33: =M33*$O$15 -> 103.14863 | P33: =M33*$P$15 -> 86.862004 | Q33: =M33*$Q$15 -> 103.14863 | R33: =M33*$R$15 -> 0 | S33: =M33*$S$15 -> 68.403825 | T33: =M33*$T$15 -> 52.1172 | U33: =M33*$U$15 -> 26.0586 | V33: =M33*$U$15 -> 26.0586 | W33: =M33*$W$15 -> 52.1172 | X33: =M33*$X$15 -> 0 | Y33: =N33*$X$15 -> 0 | Z33: =M33*$Z$15 -> 16.286625 | AA33: =M33*$AA$15 -> 0 | AB33: =M33*$AB$15 -> 65.1465 | AC33: =M33*$AC$15 -> 65.1465 | AD33: =M33*$AD$15 -> 65.1465 | AE33: =M33*$AE$15 -> 260.586 | AF33: =L33*$AH$15 -> 0 | AG33: =M33*$AG$15 -> 0 | AH33: =M33*$AH$15 -> 0
B34: Loja 8-8C | C34: =562.54-89.91 -> 472.63 | E34: 0 | F34: 701.03 | G34: 59.78 | K34: =(C34+D34+E34)*6% -> 28.3578 | L34: 0 | M34: =C34+D34+E34+F34+G34+H34+J34+L34-I34 -> 1233.44 | N34: =M34*$N$15 -> 296.0256 | O34: =M34*$O$15 -> 97.647337 | P34: =M34*$P$15 -> 82.229337 | Q34: =M34*$Q$15 -> 97.647337 | R34: =M34*$R$15 -> 0 | S34: =M34*$S$15 -> 64.7556 | T34: =M34*$T$15 -> 49.3376 | U34: =M34*$U$15 -> 24.6688 | V34: =M34*$U$15 -> 24.6688 | W34: =M34*$W$15 -> 49.3376 | X34: =M34*$X$15 -> 0 | Y34: =N34*$X$15 -> 0 | Z34: =M34*$Z$15 -> 15.418 | AA34: =M34*$AA$15 -> 0 | AB34: =M34*$AB$15 -> 61.672 | AC34: =M34*$AC$15 -> 61.672 | AD34: =M34*$AD$15 -> 61.672 | AE34: =M34*$AE$15 -> 246.688 | AF34: =L34*$AH$15 -> 0 | AG34: =M34*$AG$15 -> 0 | AH34: =M34*$AH$15 -> 0
B35: Loja 8D | C35: 594.74 | D35: 0 | E35: 0 | F35: 1189.92 | G35: 12.77 | H35: 0 | I35: 0 | J35: 0 | K35: =(C35+D35+E35)*6% -> 35.6844 | L35: 0 | M35: =C35+D35+E35+F35+G35+H35+J35+L35-I35 -> 1797.43 | N35: =M35*$N$15 -> 431.3832 | O35: =M35*$O$15 -> 142.29655 | P35: =M35*$P$15 -> 119.82867 | Q35: =M35*$Q$15 -> 142.29655 | R35: =M35*$R$15 -> 0 | S35: =M35*$S$15 -> 94.365075 | T35: =M35*$T$15 -> 71.8972 | U35: =M35*$U$15 -> 35.9486 | V35: =M35*$U$15 -> 35.9486 | W35: =M35*$W$15 -> 71.8972 | X35: =M35*$X$15 -> 0 | Y35: =N35*$X$15 -> 0 | Z35: =M35*$Z$15 -> 22.467875 | AA35: =M35*$AA$15 -> 0 | AB35: =M35*$AB$15 -> 89.8715 | AC35: =M35*$AC$15 -> 89.8715 | AD35: =M35*$AD$15 -> 89.8715 | AE35: =M35*$AE$15 -> 359.486 | AF35: =L35*$AH$15 -> 0 | AG35: =M35*$AG$15 -> 0 | AH35: =M35*$AH$15 -> 0
B36: Loja 9 | C36: =2285.89 -> 2285.89 | D36: 0 | E36: 0 | F36: 2511.34 | G36: 147.84 | H36: 0 | I36: 0 | J36: 0 | K36: =(C36+D36+E36)*6% -> 137.1534 | L36: 0 | M36: =C36+D36+E36+F36+G36+H36+J36+L36-I36 -> 4945.07 | N36: =M36*$N$15 -> 1186.8168 | O36: =M36*$O$15 -> 391.48472 | P36: =M36*$P$15 -> 329.67135 | Q36: =M36*$Q$15 -> 391.48472 | R36: =M36*$R$15 -> 0 | S36: =M36*$S$15 -> 259.61617 | T36: =M36*$T$15 -> 197.8028 | U36: =M36*$U$15 -> 98.9014 | V36: =M36*$U$15 -> 98.9014 | W36: =M36*$W$15 -> 197.8028 | X36: =M36*$X$15 -> 0 | Y36: =N36*$X$15 -> 0 | Z36: =M36*$Z$15 -> 61.813375 | AA36: =M36*$AA$15 -> 0 | AB36: =M36*$AB$15 -> 247.2535 | AC36: =M36*$AC$15 -> 247.2535 | AD36: =M36*$AD$15 -> 247.2535 | AE36: =M36*$AE$15 -> 989.014 | AF36: =L36*$AH$15 -> 0 | AG36: =M36*$AG$15 -> 0 | AH36: =M36*$AH$15 -> 0
B37: Loja 10 | C37: =2260.34 -> 2260.34 | D37: 0 | E37: 0 | F37: 1657.58 | G37: 87.48 | H37: 0 | I37: 0 | J37: 0 | K37: =(C37+D37+E37)*6% -> 135.6204 | L37: 0 | M37: =C37+D37+E37+F37+G37+H37+J37+L37-I37 -> 4005.4 | N37: =M37*$N$15 -> 961.296 | O37: =M37*$O$15 -> 317.09418 | P37: =M37*$P$15 -> 267.02668 | Q37: =M37*$Q$15 -> 317.09418 | R37: =M37*$R$15 -> 0 | S37: =M37*$S$15 -> 210.2835 | T37: =M37*$T$15 -> 160.216 | U37: =M37*$U$15 -> 80.108 | V37: =M37*$U$15 -> 80.108 | W37: =M37*$W$15 -> 160.216 | X37: =M37*$X$15 -> 0 | Y37: =N37*$X$15 -> 0 | Z37: =M37*$Z$15 -> 50.0675 | AA37: =M37*$AA$15 -> 0 | AB37: =M37*$AB$15 -> 200.27 | AC37: =M37*$AC$15 -> 200.27 | AD37: =M37*$AD$15 -> 200.27 | AE37: =M37*$AE$15 -> 801.08 | AF37: =L37*$AH$15 -> 0 | AG37: =M37*$AG$15 -> 0 | AH37: =M37*$AH$15 -> 0
B38: Loja 11 | C38: =2322.36 -> 2322.36 | D38: 0 | E38: 0 | F38: 1575.95 | G38: 83.54 | H38: 0 | I38: 0 | J38: 0 | K38: =(C38+D38+E38)*6% -> 139.3416 | L38: 0 | M38: =C38+D38+E38+F38+G38+H38+J38+L38-I38 -> 3981.85 | N38: =M38*$N$15 -> 955.644 | O38: =M38*$O$15 -> 315.2298 | P38: =M38*$P$15 -> 265.45668 | Q38: =M38*$Q$15 -> 315.2298 | R38: =M38*$R$15 -> 0 | S38: =M38*$S$15 -> 209.04713 | T38: =M38*$T$15 -> 159.274 | U38: =M38*$U$15 -> 79.637 | V38: =M38*$U$15 -> 79.637 | W38: =M38*$W$15 -> 159.274 | X38: =M38*$X$15 -> 0 | Y38: =N38*$X$15 -> 0 | Z38: =M38*$Z$15 -> 49.773125 | AA38: =M38*$AA$15 -> 0 | AB38: =M38*$AB$15 -> 199.0925 | AC38: =M38*$AC$15 -> 199.0925 | AD38: =M38*$AD$15 -> 199.0925 | AE38: =M38*$AE$15 -> 796.37 | AF38: =L38*$AH$15 -> 0 | AG38: =M38*$AG$15 -> 0 | AH38: =M38*$AH$15 -> 0
B39: Loja 12 | C39: 2201.65 | D39: 0 | E39: 0 | F39: 2915.68 | G39: 147.84 | H39: 0 | I39: 0 | J39: 0 | K39: =(C39+D39+E39)*6% -> 132.099 | L39: 0 | M39: =C39+D39+E39+F39+G39+H39+J39+L39-I39 -> 5265.17 | N39: =M39*$N$15 -> 1263.6408 | O39: =M39*$O$15 -> 416.82598 | P39: =M39*$P$15 -> 351.01135 | Q39: =M39*$Q$15 -> 416.82598 | R39: =M39*$R$15 -> 0 | S39: =M39*$S$15 -> 276.42142 | T39: =M39*$T$15 -> 210.6068 | U39: =M39*$U$15 -> 105.3034 | V39: =M39*$U$15 -> 105.3034 | W39: =M39*$W$15 -> 210.6068 | X39: =M39*$X$15 -> 0 | Y39: =N39*$X$15 -> 0 | Z39: =M39*$Z$15 -> 65.814625 | AA39: =M39*$AA$15 -> 0 | AB39: =M39*$AB$15 -> 263.2585 | AC39: =M39*$AC$15 -> 263.2585 | AD39: =M39*$AD$15 -> 263.2585 | AE39: =M39*$AE$15 -> 1053.034 | AF39: =L39*$AH$15 -> 0 | AG39: =M39*$AG$15 -> 0 | AH39: =M39*$AH$15 -> 0
B40: Loja 13 | C40: 1147.54 | D40: 0 | E40: 0 | F40: 1067.93 | G40: 63.27 | H40: 0 | I40: 0 | J40: 0 | K40: =(C40+D40+E40)*6% -> 68.8524 | L40: 0 | M40: =C40+D40+E40+F40+G40+H40+J40+L40-I40 -> 2278.74 | N40: =M40*$N$15 -> 546.8976 | O40: =M40*$O$15 -> 180.40026 | P40: =M40*$P$15 -> 151.91601 | Q40: =M40*$Q$15 -> 180.40026 | R40: =M40*$R$15 -> 0 | S40: =M40*$S$15 -> 119.63385 | T40: =M40*$T$15 -> 91.1496 | U40: =M40*$U$15 -> 45.5748 | V40: =M40*$U$15 -> 45.5748 | W40: =M40*$W$15 -> 91.1496 | X40: =M40*$X$15 -> 0 | Y40: =N40*$X$15 -> 0 | Z40: =M40*$Z$15 -> 28.48425 | AA40: =M40*$AA$15 -> 0 | AB40: =M40*$AB$15 -> 113.937 | AC40: =M40*$AC$15 -> 113.937 | AD40: =M40*$AD$15 -> 113.937 | AE40: =M40*$AE$15 -> 455.748 | AF40: =L40*$AH$15 -> 0 | AG40: =M40*$AG$15 -> 0 | AH40: =M40*$AH$15 -> 0
B41: Loja 13A | C41: =1825.86-156.69 -> 1669.17 | D41: 0 | E41: 0 | F41: 1162.03 | G41: 68.8 | H41: 0 | I41: 0 | J41: 0 | K41: =(C41+D41+E41)*6% -> 100.1502 | L41: 0 | M41: =C41+D41+E41+F41+G41+H41+J41+L41-I41 -> 2900 | N41: =M41*$N$15 -> 696 | O41: =M41*$O$15 -> 229.58334 | P41: =M41*$P$15 -> 193.33334 | Q41: =M41*$Q$15 -> 229.58334 | R41: =M41*$R$15 -> 0 | S41: =M41*$S$15 -> 152.25 | T41: =M41*$T$15 -> 116 | U41: =M41*$U$15 -> 58 | V41: =M41*$U$15 -> 58 | W41: =M41*$W$15 -> 116 | X41: =M41*$X$15 -> 0 | Y41: =N41*$X$15 -> 0 | Z41: =M41*$Z$15 -> 36.25 | AA41: =M41*$AA$15 -> 0 | AB41: =M41*$AB$15 -> 145 | AC41: =M41*$AC$15 -> 145 | AD41: =M41*$AD$15 -> 145 | AE41: =M41*$AE$15 -> 580 | AF41: =L41*$AH$15 -> 0 | AG41: =M41*$AG$15 -> 0 | AH41: =M41*$AH$15 -> 0
B42: Loja 14 | C42: 876.97 | D42: 0 | E42: 0 | F42: 565.64 | G42: 97.34 | H42: 0 | I42: 0 | J42: 0 | K42: =(C42+D42+E42)*6% -> 52.6182 | L42: 0 | M42: =C42+D42+E42+F42+G42+H42+J42+L42-I42 -> 1539.95 | N42: =M42*$N$15 -> 369.588 | O42: =M42*$O$15 -> 121.91271 | P42: =M42*$P$15 -> 102.66334 | Q42: =M42*$Q$15 -> 121.91271 | R42: =M42*$R$15 -> 0 | S42: =M42*$S$15 -> 80.847375 | T42: =M42*$T$15 -> 61.598 | U42: =M42*$U$15 -> 30.799 | V42: =M42*$U$15 -> 30.799 | W42: =M42*$W$15 -> 61.598 | X42: =M42*$X$15 -> 0 | Y42: =N42*$X$15 -> 0 | Z42: =M42*$Z$15 -> 19.249375 | AA42: =M42*$AA$15 -> 0 | AB42: =M42*$AB$15 -> 76.9975 | AC42: =M42*$AC$15 -> 76.9975 | AD42: =M42*$AD$15 -> 76.9975 | AE42: =M42*$AE$15 -> 307.99 | AF42: =L42*$AH$15 -> 0 | AG42: =M42*$AG$15 -> 0 | AH42: =M42*$AH$15 -> 0
B43: Loja 15 | C43: =1848.21 -> 1848.21 | D43: 0 | E43: 0 | F43: 681.87 | G43: 52.56 | H43: 0 | I43: 0 | J43: 0 | K43: =(C43+D43+E43)*6% -> 110.8926 | L43: 0 | M43: =C43+D43+E43+F43+G43+H43+J43+L43-I43 -> 2582.64 | N43: =M43*$N$15 -> 619.8336 | O43: =M43*$O$15 -> 204.45901 | P43: =M43*$P$15 -> 172.17601 | Q43: =M43*$Q$15 -> 204.45901 | R43: =M43*$R$15 -> 0 | S43: =M43*$S$15 -> 135.5886 | T43: =M43*$T$15 -> 103.3056 | U43: =M43*$U$15 -> 51.6528 | V43: =M43*$U$15 -> 51.6528 | W43: =M43*$W$15 -> 103.3056 | X43: =M43*$X$15 -> 0 | Y43: =N43*$X$15 -> 0 | Z43: =M43*$Z$15 -> 32.283 | AA43: =M43*$AA$15 -> 0 | AB43: =M43*$AB$15 -> 129.132 | AC43: =M43*$AC$15 -> 129.132 | AD43: =M43*$AD$15 -> 129.132 | AE43: =M43*$AE$15 -> 516.528 | AF43: =L43*$AH$15 -> 0 | AG43: =M43*$AG$15 -> 0 | AH43: =M43*$AH$15 -> 0
B44: Loja 17 | C44: 1137.96 | D44: =127.3+54.39+109.17 -> 290.86 | E44: 0 | F44: 675.04 | G44: 0 | H44: 0 | I44: 0 | J44: 0 | K44: =(C44+D44+E44)*6% -> 85.7292 | L44: 0 | M44: =C44+D44+E44+F44+G44+H44+J44+L44-I44 -> 2103.86 | N44: =M44*$N$15 -> 504.9264 | O44: =M44*$O$15 -> 166.55559 | P44: =M44*$P$15 -> 140.25734 | Q44: =M44*$Q$15 -> 166.55559 | R44: =M44*$R$15 -> 0 | S44: =M44*$S$15 -> 110.45265 | T44: =M44*$T$15 -> 84.1544 | U44: =M44*$U$15 -> 42.0772 | V44: =M44*$U$15 -> 42.0772 | W44: =M44*$W$15 -> 84.1544 | X44: =M44*$X$15 -> 0 | Y44: =N44*$X$15 -> 0 | Z44: =M44*$Z$15 -> 26.29825 | AA44: =M44*$AA$15 -> 0 | AB44: =M44*$AB$15 -> 105.193 | AC44: =M44*$AC$15 -> 105.193 | AD44: =M44*$AD$15 -> 105.193 | AE44: =M44*$AE$15 -> 420.772 | AF44: =L44*$AH$15 -> 0 | AG44: =M44*$AG$15 -> 0 | AH44: =M44*$AH$15 -> 0
B45: Loja 17A | C45: =1269.15-800 -> 469.15 | D45: 0 | E45: 0 | F45: 508.95 | G45: 21.9 | H45: 0 | I45: 0 | J45: 0 | K45: =(C45+D45+E45)*6% -> 28.149 | L45: 0 | M45: =C45+D45+E45+F45+G45+H45+J45+L45-I45 -> 1000 | N45: =M45*$N$15 -> 240 | O45: =M45*$O$15 -> 79.16667 | P45: =M45*$P$15 -> 66.66667 | Q45: =M45*$Q$15 -> 79.16667 | R45: =M45*$R$15 -> 0 | S45: =M45*$S$15 -> 52.5 | T45: =M45*$T$15 -> 40 | U45: =M45*$U$15 -> 20 | V45: =M45*$U$15 -> 20 | W45: =M45*$W$15 -> 40 | X45: =M45*$X$15 -> 0 | Y45: =N45*$X$15 -> 0 | Z45: =M45*$Z$15 -> 12.5 | AA45: =M45*$AA$15 -> 0 | AB45: =M45*$AB$15 -> 50 | AC45: =M45*$AC$15 -> 50 | AD45: =M45*$AD$15 -> 50 | AE45: =M45*$AE$15 -> 200 | AF45: =L45*$AH$15 -> 0 | AG45: =M45*$AG$15 -> 0 | AH45: =M45*$AH$15 -> 0
...

Sheet Dist. Despesas
B5: DISTRIBUIÇÃO DE DESPESAS - MAIO/2026
B7: DESPESAS | C7: VALOR | D7: ROPSIME C | E7: CAROLINE | F7: THYAGO | G7: FREDERICO | H7: EDDA | I7: CLAUDINA | J7: VARAM | K7: M. TERESA | L7: HENRIQUE G. | M7: ADRIANA | N7: CAROLINA | O7: FKZ | P7: M. ANTONIO | Q7: JULIANA | R7: MONIQUE | S7: VIVIANNE | T7: DENISE | U7: ROPSIMÉ | V7: KEUTE | W7: HALLELUJAH | X7: ROKE
D8: 0.24 | E8: 0.07916667 | F8: 0.06666667 | G8: 0.07916667 | H8: 0 | I8: 0.0525 | J8: 0.04 | K8: 0.02 | L8: 0.02 | M8: 0.04 | N8: 0 | O8: 0 | P8: 0.0125 | Q8: 0 | R8: 0.05 | S8: 0.05 | T8: 0.05 | U8: 0.2 | V8: 0 | W8: 0 | X8: 0
B9: Honorários Administrativos - Ed. Claudina | C9: =SUM(Receitas!K12:K296) -> 7751.1354 | D9: =C9*$D$8 -> 1860.2725 | E9: =$C$9*E8 -> 613.63158 | F9: =$C$9*F8 -> 516.74239 | G9: =$C$9*G8 -> 613.63158 | H9: =$C$9*H8 -> 0 | I9: =$C$9*I8 -> 406.93461 | J9: =$C$9*J8 -> 310.04542 | K9: =$C$9*K8 -> 155.02271 | L9: =$C$9*L8 -> 155.02271 | ... X9: =$C$9*X8 -> 0
B10: Retenção Fundo de Reserva Ed. Claudina - (3%) | C10: =C11*3% -> 5406.4209 | D10: =C10*$D$8 -> 1297.541 | E10: =$C$10*E8 -> 428.00834 | F10: =$C$10*F8 -> 360.42808 | G10: =$C$10*G8 -> 428.00834 | H10: =$C$10*H8 -> 0 | I10: =$C$10*I8 -> 283.8371 | J10: =$C$10*J8 -> 216.25684 | K10: =$C$10*K8 -> 108.12842 | L10: =$C$10*L8 -> 108.12842 | ... X10: =$C$10*X8 -> 0
B11: Condomínios - Ed. Claudina + IPTU | C11: =19440.6+160773.43 -> 180214.03 | D11: =C11*$D$8 -> 43251.367 | E11: =$C$11*E8 -> 14266.945 | F11: =$C$11*F8 -> 12014.269 | G11: =$C$11*G8 -> 14266.945 | H11: =$C$11*H8 -> 0 | I11: =$C$11*I8 -> 9461.2366 | J11: =$C$11*J8 -> 7208.5612 | K11: =$C$11*K8 -> 3604.2806 | L11: =$C$11*L8 -> 3604.2806 | ... X11: =$C$11*X8 -> 0
B12: Despesas com Cartório - Marcos K. e Outros | C12: 0 | D12: =C12*$D$8 -> 0 | E12: =$C$12*E8 -> 0 | F12: =$C$12*F8 -> 0 | G12: =$C$12*G8 -> 0 | H12: =$C$12*H8 -> 0 | I12: =$C$12*I8 -> 0 | J12: =$C$12*J8 -> 0 | K12: =$C$12*K8 -> 0 | L12: =$C$12*L8 -> 0 | ... X12: =$C$12*X8 -> 0
B13: Guias Judiciais - Processo CE Claudina | C13: 0 | D13: =C13*$D$8 -> 0 | E13: =$C$13*E8 -> 0 | F13: =$C$13*F8 -> 0 | G13: =$C$13*G8 -> 0 | H13: =$C$13*H8 -> 0 | I13: =$C$13*I8 -> 0 | J13: =$C$13*J8 -> 0 | K13: =$C$13*K8 -> 0 | L13: =$C$13*L8 -> 0 | ... X13: =$C$13*X8 -> 0
B14: SUB TOTAL: | C14: =SUM(C9:C13) -> 193371.59 | D14: =SUM(D9:D13) -> 46409.181 | E14: =SUM(E9:E13) -> 15308.585 | F14: =SUM(F9:F13) -> 12891.44 | G14: =SUM(G9:G13) -> 15308.585 | H14: =SUM(H9:H13) -> 0 | I14: =SUM(I9:I13) -> 10152.008 | J14: =SUM(J9:J13) -> 7734.8635 | ... X14: =SUM(X9:X13) -> 0
B15: DESPESAS | C15: VALOR | D15: ROPSIME C | E15: CAROLINE | F15: THYAGO | G15: FREDERICO | H15: EDDA | I15: CLAUDINA | J15: VARAM | K15: M. TERESA | L15: HENRIQUE G. | M15: ADRIANA | N15: CAROLINA | O15: FKZ | P15: M. ANTONIO | Q15: JULIANA | R15: MONIQUE | S15: VIVIANNE | T15: DENISE | U15: ROPSIMÉ | V15: KEUTE | W15: HALLELUJAH | X15: ROKE
D16: 0.24 | E16: 0 | F16: 0 | G16: 0 | H16: 0 | I16: 0.04 | J16: 0.04 | K16: 0.02 | L16: 0.02 | M16: 0 | N16: 0 | O16: 0.04 | P16: 0 | Q16: 0.05 | R16: 0.05 | S16: 0.05 | T16: 0.05 | U16: 0 | V16: 0.1 | W16: 0.1 | X16: 0.2
B17: Honorários administrativos - Outros Imóveis | C17: =SUM(Receitas!K8:K11) -> 15288.74 | D17: =$C$17*D16 -> 3669.2976 | E17: 0 | F17: =$C$17*F16 -> 0 | G17: 0 | H17: =$C$17*H16 -> 0 | I17: =$C$17*I16 -> 611.54959 | J17: =$C$17*J16 -> 611.54959 | K17: =$C$17*K16 -> 305.7748 | L17: =$C$17*L16 -> 305.7748 | M17: =$C$17*M16 -> 0 | N17: =$C$17*N16 -> 0 | O17: =$C$17*O16 -> 611.54959 | ... T17: =$C$17*T16 -> 764.43699 | U17: 0 | V17: =$C$17*V16 -> 1528.874 | W17: =$C$17*W16 -> 1528.874 | X17: =C17*X16 -> 3057.748
B18: SUB TOTAL: | C18: =SUM(C17:C17) -> 15288.74 | D18: =SUM(D17:D17) -> 3669.2976 | E18: =SUM(E17:E17) -> 0 | F18: =SUM(F17:F17) -> 0 | G18: =SUM(G17:G17) -> 0 | H18: =SUM(H17:H17) -> 0 | I18: =SUM(I17:I17) -> 611.54959 | J18: =SUM(J17:J17) -> 611.54959 | ... X18: =SUM(X17:X17) -> 3057.748
B19: DESPESAS | C19: VALOR | D19: ROPSIME C | E19: CAROLINE | F19: THYAGO | G19: FREDERICO | H19: EDDA | I19: CLAUDINA | J19: VARAM | K19: M. TERESA | L19: HENRIQUE G. | M19: ADRIANA | N19: CAROLINA | O19: FKZ | P19: M. ANTONIO | Q19: JULIANA | R19: MONIQUE | S19: VIVIANNE | T19: DENISE | U19: ROPSIMÉ | V19: KEUTE | W19: HALLELUJAH | X19: ROKE
D20: 0.24 | E20: 0 | F20: 0 | G20: 0 | H20: 0 | I20: 0.04 | J20: 0.04 | K20: 0.02 | L20: 0.02 | M20: 0 | N20: 0 | O20: 0.04 | P20: 0 | Q20: 0.05 | R20: 0.05 | S20: 0.05 | T20: 0.05 | U20: 0 | V20: 0.1 | W20: 0.1 | X20: 0.2
B21: IPTU - Parcela 03/10 - Florêncio de Abreu 60,66,70 e 74 | C21: 23604.48 | D21: =C21*$D$20 -> 5665.0752 | E21: 0 | F21: =$C$21*F20 -> 0 | G21: =$C$21*G20 -> 0 | H21: =$C$21*H20 -> 0 | I21: =$C$21*I20 -> 944.1792 | J21: =$C$21*J20 -> 944.1792 | K21: =$C$21*K20 -> 472.0896 | L21: =$C$21*L20 -> 472.0896 | M21: =$C$21*M20 -> 0 | ... X21: =$C$21*X20 -> 4720.896
B22: IPTU - Parcela 04/10 - R. 25 de Março, 661,669 | C22: 31813.47 | D22: =C22*$D$20 -> 7635.2328 | E22: =$C$22*E20 -> 0 | F22: =$C$22*F20 -> 0 | G22: =$C$22*G20 -> 0 | H22: =$C$22*H20 -> 0 | I22: =$C$22*I20 -> 1272.5388 | J22: =$C$22*J20 -> 1272.5388 | K22: =$C$22*K20 -> 636.2694 | L22: =$C$22*L20 -> 636.2694 | ... X22: =$C$22*X20 -> 6362.694
B23: Regularização - 25 de Março | C23: 0 | D23: =C23*$D$20 -> 0 | E23: =$C$23*E20 -> 0 | F23: =$C$23*F20 -> 0 | G23: =$C$23*G20 -> 0 | H23: =$C$23*H20 -> 0 | I23: =$C$23*I20 -> 0 | J23: =$C$23*J20 -> 0 | K23: =$C$23*K20 -> 0 | L23: =$C$23*L20 -> 0 | ... X23: =$C$23*X20 -> 0
B24: ThyssenKrupp - 25 de Março | C24: =1451.81+1051.25+4637.69 -> 7140.75 | D24: =C24*$D$20 -> 1713.78 | E24: =$C$24*E20 -> 0 | F24: =$C$24*F20 -> 0 | G24: =$C$24*G20 -> 0 | H24: =$C$24*H20 -> 0 | I24: =$C$24*I20 -> 285.63 | J24: =$C$24*J20 -> 285.63 | K24: =$C$24*K20 -> 142.815 | L24: =$C$24*L20 -> 142.815 | ... X24: =$C$24*X20 -> 1428.15
B25: SUB TOTAL: | C25: =SUM(C21:C24) -> 62558.7 | D25: =SUM(D21:D24) -> 15014.088 | E25: =SUM(E21:E24) -> 0 | F25: =SUM(F21:F24) -> 0 | G25: =SUM(G21:G24) -> 0 | H25: =SUM(H21:H24) -> 0 | I25: =SUM(I21:I24) -> 2502.348 | J25: =SUM(J21:J24) -> 2502.348 | ... X25: =SUM(X21:X24) -> 12511.74
B26: DESPESAS | C26: VALOR | D26: ROPSIME C | E26: CAROLINE | F26: THYAGO | G26: FREDERICO | H26: EDDA | I26: CLAUDINA | J26: VARAM | K26: M. TERESA | L26: HENRIQUE G. | M26: ADRIANA | N26: CAROLINA | O26: FKZ | P26: M. ANTONIO | Q26: JULIANA | R26: MONIQUE | S26: VIVIANNE | T26: DENISE | U26: ROPSIMÉ | V26: KEUTE | W26: HALLELUJAH | X26: ROKE
D27: 0.3333333 | E27: 0.11111111 | F27: 0.11111111 | G27: 0.11111111 | H27: 0.25 | I27: 0.01666667 | J27: 0.01666667 | K27: 0.00833333 | L27: =K27 -> 0.00833333 | M27: 0.01666667 | N27: 0.01666667 | O27: 0 | P27: 0 | Q27: 0 | R27: 0 | S27: 0 | T27: 0 | U27: 0 | V27: 0 | W27: 0 | X27: 0
B28: IPTU - Parcela 03/10 - R. Maria Amália L Azevedo, S/N | C28: 2261.93 | D28: =C28*$D$27 -> 753.97659 | E28: =$C$28*E27 -> 251.32555 | F28: =$C$28*F27 -> 251.32555 | G28: =$C$28*G27 -> 251.32555 | H28: =$C$28*H27 -> 565.4825 | I28: =$C$28*I27 -> 37.698841 | J28: =$C$28*J27 -> 37.698841 | K28: =$C$28*K27 -> 18.849409 | L28: =$C$28*L27 -> 18.849409 | ... X28: =$C$28*X27 -> 0
B29: Despesas - Limpeza do Terreno | C29: 2000 | D29: =$C$29*D27 -> 666.6666 | E29: =$C$29*E27 -> 222.22222 | F29: =$C$29*F27 -> 222.22222 | G29: =$C$29*G27 -> 222.22222 | H29: =$C$29*H27 -> 500 | I29: =$C$29*I27 -> 33.33334 | J29: =$C$29*J27 -> 33.33334 | K29: =$C$29*K27 -> 16.66666 | ... X29: =$C$29*X27 -> 0
B30: SUB TOTAL: | C30: =SUM(C28:C29) -> 4261.93 | D30: =SUM(D28:D29) -> 1420.6432 | E30: =SUM(E28:E29) -> 473.54777 | F30: =SUM(F28:F29) -> 473.54777 | G30: =SUM(G28:G29) -> 473.54777 | H30: =SUM(H28:H29) -> 1065.4825 | I30: =SUM(I28:I29) -> 71.032181 | J30: =SUM(J28:J29) -> 71.032181 | ... X30: =SUM(X28:X29) -> 0
B31: DESPESAS INDIVIDUAIS | C31: VALOR | D31: ROPSIME C | E31: CAROLINE | F31: THYAGO | G31: FREDERICO | H31: EDDA | I31: CLAUDINA | J31: VARAM | K31: M. TERESA | L31: HENRIQUE G. | M31: ADRIANA | N31: CAROLINA | O31: FKZ | P31: M. ANTONIO | Q31: JULIANA | R31: MONIQUE | S31: VIVIANNE | T31: DENISE | U31: ROPSIMÉ | V31: KEUTE | W31: HALLELUJAH | X31: ROKE
B33: Despesas Extraordináris - 5 Irmãos | C33: =1059.56 -> 1059.56 | D33: =C33*24% -> 254.2944 | E33: =$C$33*6.66667% -> 70.637369 | F33: =$C$33*6.66667% -> 70.637369 | G33: =$C$33*6.66667% -> 70.637369 | H33: 0 | I33: =$C$33*4% -> 42.3824 | J33: =$C$33*4% -> 42.3824 | K33: =$C$33*2% -> 21.1912 | L33: =$C$33*2% -> 21.1912 | M33: =$C$33*4% -> 42.3824 | N33: 0 | O33: 0 | P33: 0 | Q33: =$C$33*5% -> 52.978 | R33: =$C$33*5% -> 52.978 | S33: =$C$33*5% -> 52.978 | T33: =$C$33*5% -> 52.978 | U33: =C33*20% -> 211.912 | V33: 0 | W33: 0 | X33: 0
B34: Honorários Advocatícios(Astúrias Guarujá) | C34: =10000+1612.68+(46.57*11) -> 12124.95 | D34: 0 | E34: =$C$34/4/3 -> 1010.4125 | F34: =$C$34/4/3 -> 1010.4125 | G34: =$C$34/4/3 -> 1010.4125 | H34: =(C34/4)*0.75 -> 2273.4281 | I34: =$C$34/4*0.05 -> 151.56188 | J34: =$C$34/4*0.05 -> 151.56188 | K34: =$C$34/4*0.05/2 -> 75.780938 | L34: =$C$34/4*0.05/2 -> 75.780938 | M34: =$C$34/4*0.05 -> 151.56188 | N34: =$C$34/4*0.05 -> 151.56188 | O34: 0 | P34: 0 | Q34: =$C$34/4/4 -> 757.80938 | R34: =$C$34/4/4 -> 757.80938 | S34: =$C$34/4/4 -> 757.80938 | T34: =$C$34/4/4 -> 757.80938 | U34: =C34/4 -> 3031.2375 | V34: 0 | W34: 0 | X34: 0
B35: Despesas - Pericia Iguape | C35: 50000 | D35: 0 | E35: =C35/4/3 -> 4166.6667 | F35: =E35 -> 4166.6667 | G35: =F35 -> 4166.6667 | H35: =C35/4/2 -> 6250 | I35: =(C35/4/2)/5 -> 1250 | J35: =I35 -> 1250 | K35: =J35/2 -> 625 | L35: =K35 -> 625 | M35: =J35 -> 1250 | N35: =M35 -> 1250 | O35: 0 | P35: 0 | Q35: =C35/4/4 -> 3125 | R35: =Q35 -> 3125 | S35: =R35 -> 3125 | T35: =S35 -> 3125 | U35: =C35/4 -> 12500 | V35: 0 | W35: 0 | X35: 0
B36: Despesas - M. Teresa Gasparian | C36: 0 | D36: 0 | E36: 0 | F36: 0 | G36: 0 | H36: 0 | I36: 0 | J36: 0 | K36: =C36/2 -> 0 | L36: =K36 -> 0 | M36: 0 | N36: 0 | O36: 0 | P36: 0 | Q36: 0 | R36: 0 | S36: 0 | T36: 0 | U36: 0 | V36: 0 | W36: 0 | X36: 0
B37: Despesas - Vivianne H. | C37: 0 | D37: 0 | E37: 0 | F37: 0 | G37: 0 | H37: 0 | I37: 0 | J37: 0 | K37: 0 | L37: 0 | M37: 0 | N37: 0 | O37: 0 | P37: 0 | Q37: 0 | R37: 0 | S37: =C37 -> 0 | T37: 0 | U37: 0 | V37: 0 | W37: 0 | X37: 0
B38: Despesas - Ropsime Claudina V Keutenedjian | C38: 10092.3 | D38: =C38 -> 10092.3 | E38: 0 | F38: 0 | G38: 0 | H38: 0 | I38: 0 | J38: 0 | K38: 0 | L38: 0 | M38: 0 | N38: 0 | O38: 0 | P38: 0 | Q38: 0 | R38: 0 | S38: 0 | T38: 0 | U38: 0 | V38: 0 | W38: 0 | X38: 0
B39: Repasse (Mônica Lewandowski) | C39: =1161.3+8320.82 -> 9482.12 | D39: 0 | E39: 0 | F39: 0 | G39: 0 | H39: 0 | I39: 0 | J39: 0 | K39: 0 | L39: 0 | M39: 0 | N39: 0 | O39: 0 | P39: 0 | Q39: 0 | R39: =C39 -> 9482.12 | S39: 0 | T39: 0 | U39: 0 | V39: 0 | W39: 0 | X39: 0
B40: Repasse (Denise Haddad) | C40: =1161.3+8322.39 -> 9483.69 | D40: 0 | E40: 0 | F40: 0 | G40: 0 | H40: 0 | I40: 0 | J40: 0 | K40: 0 | L40: 0 | M40: 0 | N40: 0 | O40: 0 | P40: 0 | Q40: 0 | R40: 0 | S40: 0 | T40: =C40 -> 9483.69 | U40: 0 | V40: 0 | W40: 0 | X40: 0
B41: Repasse (Viviane Haddad) | C41: =8320.82+1161.3 -> 9482.12 | D41: 0 | E41: 0 | F41: 0 | G41: 0 | H41: 0 | I41: 0 | J41: 0 | K41: 0 | L41: 0 | M41: 0 | N41: 0 | O41: 0 | P41: 0 | Q41: 0 | R41: 0 | S41: =C41 -> 9482.12 | T41: 0 | U41: 0 | V41: 0 | W41: 0 | X41: 0
B42: Repasse (Juliana Mattos Haddad) | C42: 11096.52 | D42: 0 | E42: 0 | F42: 0 | G42: 0 | H42: 0 | I42: 0 | J42: 0 | K42: 0 | L42: 0 | M42: 0 | N42: 0 | O42: 0 | P42: 0 | Q42: =C42 -> 11096.52 | R42: 0 | S42: 0 | T42: 0 | U42: 0 | V42: 0 | W42: 0 | X42: 0
B43: Repasse (Marco Antônio Keutenedjian Milani) | C43: =290.33 -> 290.33 | D43: 0 | E43: 0 | F43: 0 | G43: 0 | H43: 0 | I43: 0 | J43: 0 | K43: 0 | L43: 0 | M43: 0 | N43: 0 | O43: 0 | P43: =C43 -> 290.33 | Q43: 0 | R43: 0 | S43: 0 | T43: 0 | U43: 0 | V43: 0 | W43: 0 | X43: 0
B44: Repasse(Claudina Keutenedjian) | C44: =1219.37+8758.75 -> 9978.12 | D44: 0 | E44: 0 | F44: 0 | G44: 0 | H44: 0 | I44: =C44 -> 9978.12 | J44: 0 | K44: 0 | L44: 0 | M44: 0 | N44: 0 | O44: 0 | P44: 0 | Q44: 0 | R44: 0 | S44: 0 | T44: 0 | U44: 0 | V44: 0 | W44: 0 | X44: 0
B45: Repasse (Adriana Keutenedjian) | C45: =929.04 -> 929.04 | D45: 0 | E45: 0 | F45: 0 | G45: 0 | H45: 0 | I45: 0 | J45: 0 | K45: 0 | L45: 0 | M45: =C45 -> 929.04 | N45: 0 | O45: 0 | P45: 0 | Q45: 0 | R45: 0 | S45: 0 | T45: 0 | U45: 0 | V45: 0 | W45: 0 | X45: 0
B46: Repasse (Varam Keutenedjian Neto) | C46: =929.04+8758.75 -> 9687.79 | D46: 0 | E46: 0 | F46: 0 | G46: 0 | H46: 0 | I46: 0 | J46: =C46 -> 9687.79 | K46: 0 | L46: 0 | M46: 0 | N46: 0 | O46: 0 | P46: 0 | Q46: 0 | R46: 0 | S46: 0 | T46: 0 | U46: 0 | V46: 0 | W46: 0 | X46: 0
...

Sheet Saldo Individual
B5: SALDOS INDIVIDUAIS - MAIO/2026
C6: SALDO ANTERIOR | D6: RECEITAS DO MÊS | E6: DESPESAS DO MÊS | F6: SALDO ATUAL
B7: ROPSIME CLAUDINA VARAM KEUTENEDJIAN | C7: 18842.932 | D7: ='Dist. Receitas'!N303 -> 124254.23 | E7: ='Dist. Despesas'!D61 -> -118637.01 | F7: =C7+D7+E7 -> 24460.148
B9: CAROLINE CORDEIRO KEUTENEDJIAN | C9: 9797.9069 | D9: ='Dist. Receitas'!O303 -> 19462.523 | E9: ='Dist. Despesas'!E61 -> -22868.579 | F9: =C9+D9+E9 -> 6391.8514
B11: THYAGO BAPTISTA CORDEIRO KEUTENEDJIAN | C11: -41773.088 | D11: ='Dist. Receitas'!P303 -> 16389.493 | E11: ='Dist. Despesas'!F61 -> -18612.704 | F11: =C11+D11+E11 -> -43996.299
B13: FREDERICO CORDEIRO KEUTENEDJIAN | C13: 15584.597 | D13: ='Dist. Receitas'!Q303 -> 19462.523 | E13: ='Dist. Despesas'!G61 -> -22868.579 | F13: =C13+D13+E13 -> 12178.541
B15: KEUTE ADMINISTRAÇÃO E PARTICIPAÇÕES | C15: 9582.712 | D15: ='Dist. Receitas'!AF303 -> 30485.511 | E15: ='Dist. Despesas'!V61 -> -29920.904 | F15: =C15+D15+E15 -> 10147.319
B17: HALLELUJAH PARTICIPAÇÕES LTDA | C17: 9582.711 | D17: ='Dist. Receitas'!AG303 -> 30485.511 | E17: ='Dist. Despesas'!W61 -> -29920.904 | F17: =C17+D17+E17 -> 10147.318
B19: CLAUDINA VARAM KEUTENEDJIAN MAKHOUL | C19: 11411.459 | D19: ='Dist. Receitas'!S303 -> 24678.49 | E19: ='Dist. Despesas'!I61 -> -24759.002 | F19: =C19+D19+E19 -> 11330.946
B21: VARAM KEUTENEDJIAN NETO | C21: 7484.6618 | D21: ='Dist. Receitas'!T303 -> 21605.46 | E21: ='Dist. Despesas'!J61 -> -22051.527 | F21: =C21+D21+E21 -> 7038.5943
B23: MARIA TERESA GASPARIAN KEUTENEDJIAN | C23: 1468.8562 | D23: ='Dist. Receitas'!U303 -> 11013.95 | E23: ='Dist. Despesas'!K61 -> -11236.979 | F23: =C23+D23+E23 -> 1245.8274
B25: HENRIQUE GASPARIAN KEUTENEDJIAN | C25: 1468.8562 | D25: ='Dist. Receitas'!V303 -> 11013.95 | E25: ='Dist. Despesas'!L61 -> -11236.979 | F25: =C25+D25+E25 -> 1245.8274
B27: MARIA CAROLINA VARAM KEUTENEDJIAN MADY | C27: -392.06141 | D27: ='Dist. Receitas'!X303 -> 0 | E27: ='Dist. Despesas'!N61 -> -1472.5941 | F27: =C27+D27+E27 -> -1864.6555
B29: ADRIANA VARAM KEUTENEDJIAN ZIMMERMANN | C29: 343.91149 | D29: ='Dist. Receitas'!W303 -> 9833.6956 | E29: ='Dist. Despesas'!M61 -> -10178.88 | F29: =C29+D29+E29 -> -1.2728173
B31: FKZ INVESTIMENTOS E PARTICIPACOES | C31: -7198.3977 | D31: ='Dist. Receitas'!Y303 -> 12194.204 | E31: ='Dist. Despesas'!O61 -> -12295.088 | F31: =C31+D31+E31 -> -7299.2809
B33: CARLOS ANIBAL HADDAD | C33: 0 | D33: 0 | E33: ='Dist. Despesas'!M63 -> 0 | F33: =C33+D33+E33 -> 0
B35: JULIANA MATOS HADDAD | C35: -1485.2629 | D35: ='Dist. Receitas'!AA303 -> 14445.785 | E35: ='Dist. Despesas'!Q61 -> -18924.679 | F35: =C35+D35+E35 -> -5964.1568
B37: MONIQUE HADDAD LEWANDOWSKY | C37: 19689.101 | D37: ='Dist. Receitas'!AB303 -> 26737.905 | E37: ='Dist. Despesas'!R61 -> -26978.859 | F37: =C37+D37+E37 -> 19448.147
B39: VIVIANNE HADDAD MORUZZI | C39: 13630.041 | D39: ='Dist. Receitas'!AC303 -> 26737.905 | E39: ='Dist. Despesas'!S61 -> -26978.859 | F39: =C39+D39+E39 -> 13389.087
B41: DENISE HADDAD | C41: 16098.501 | D41: ='Dist. Receitas'!AD303 -> 27534.875 | E41: ='Dist. Despesas'!T61 -> -26980.429 | F41: =C41+D41+E41 -> 16652.947
B43: ROPSIMÉ KEUTENEDJIAN MILANI | C43: 53867.069 | D43: ='Dist. Receitas'!AE303 -> 49168.478 | E43: ='Dist. Despesas'!U61 -> -59062.677 | F43: =C43+D43+E43 -> 43972.87
B45: EDDA MILANI KEUTENEDJIAN | C45: -34856.618 | D45: ='Dist. Receitas'!R303 -> 0 | E45: ='Dist. Despesas'!H61 -> -9588.9106 | F45: =C45+D45+E45 -> -44445.529
B47: ROKE LTDA. | C47: 11220.144 | D47: ='Dist. Receitas'!AH303 -> 60971.022 | E47: ='Dist. Despesas'!X61 -> -59955.568 | F47: =C47+D47+E47 -> 12235.598
B49: MARCO ANTÔNIO KEUTENEDJIAN MILANI | C49: 1231.2671 | D49: ='Dist. Receitas'!Z303 -> 3073.0299 | E49: ='Dist. Despesas'!P61 -> -2707.4748 | F49: =C49+D49+E49 -> 1596.8221
